{
 "cells": [
  {
   "cell_type": "code",
   "execution_count": 1,
   "metadata": {},
   "outputs": [],
   "source": [
    "# My imports"
   ]
  },
  {
   "cell_type": "markdown",
   "metadata": {},
   "source": [
    "# Error Handling"
   ]
  },
  {
   "cell_type": "markdown",
   "metadata": {},
   "source": [
    "In any program, things can go wrong. Files may not exist, invalid user input can occur, or operations might fail. Error handling allows you to manage these issues without crashing the program, offering a graceful way to handle exceptions.\n",
    "\n",
    "* Importance of Error Handling:\n",
    "\n",
    "    * Prevents program crashes.\n",
    "    * Improves user experience by providing informative error messages.\n",
    "    * Helps ensure that critical operations (like closing files or releasing resources) always happen.\n"
   ]
  },
  {
   "cell_type": "markdown",
   "metadata": {},
   "source": [
    "### Common Python Errors"
   ]
  },
  {
   "cell_type": "markdown",
   "metadata": {},
   "source": [
    "There are several common errors in Python that you'll encounter. Understanding them is the first step to handling them:\n",
    "\n",
    "* **SyntaxError:** Raised when there is a syntax error in the code.\n",
    "* **NameError:** Raised when a variable or function is not defined.\n",
    "* **TypeError:** Raised when an operation or function is applied to an object of inappropriate type.\n",
    "* **ValueError:** Raised when a function receives an argument of the correct type but an inappropriate value.\n",
    "* **FileNotFoundError:** Raised when a file or directory is requested but cannot be found.\n"
   ]
  },
  {
   "cell_type": "code",
   "execution_count": 5,
   "metadata": {},
   "outputs": [
    {
     "ename": "ValueError",
     "evalue": "invalid literal for int() with base 10: 'ABC'",
     "output_type": "error",
     "traceback": [
      "\u001b[0;31m---------------------------------------------------------------------------\u001b[0m",
      "\u001b[0;31mValueError\u001b[0m                                Traceback (most recent call last)",
      "Cell \u001b[0;32mIn[5], line 2\u001b[0m\n\u001b[1;32m      1\u001b[0m \u001b[38;5;66;03m# Example of ValueError\u001b[39;00m\n\u001b[0;32m----> 2\u001b[0m \u001b[38;5;28;43mint\u001b[39;49m\u001b[43m(\u001b[49m\u001b[38;5;124;43m\"\u001b[39;49m\u001b[38;5;124;43mABC\u001b[39;49m\u001b[38;5;124;43m\"\u001b[39;49m\u001b[43m)\u001b[49m  \u001b[38;5;66;03m# Can't convert a string to an integer\u001b[39;00m\n",
      "\u001b[0;31mValueError\u001b[0m: invalid literal for int() with base 10: 'ABC'"
     ]
    }
   ],
   "source": [
    "# Example of ValueError\n",
    "int(\"ABC\")  # Can't convert a string to an integer"
   ]
  },
  {
   "cell_type": "markdown",
   "metadata": {},
   "source": [
    "### The try, except, else, and finally Structure\n",
    "\n",
    "Python provides a structured way to handle exceptions using the try, except, else, and finally blocks.\n",
    "\n",
    "* try: Code that might raise an exception is placed here.\n",
    "* except: Code to handle exceptions is placed here.\n",
    "* else: Code that should run if no exceptions are raised goes here.\n",
    "* finally: Code that runs no matter what (used for cleanup operations)."
   ]
  },
  {
   "cell_type": "code",
   "execution_count": 7,
   "metadata": {},
   "outputs": [
    {
     "name": "stdout",
     "output_type": "stream",
     "text": [
      "You entered: 123\n",
      "Execution complete.\n"
     ]
    }
   ],
   "source": [
    "try:\n",
    "    number = int(input(\"Enter a number: \"))\n",
    "except ValueError:\n",
    "    print(\"That was not a valid number!\")\n",
    "else:\n",
    "    print(\"You entered:\", number)\n",
    "finally:\n",
    "    print(\"Execution complete.\")"
   ]
  },
  {
   "cell_type": "markdown",
   "metadata": {},
   "source": [
    "In this example, if the input is not a valid number, a ValueError is caught, and the program continues without crashing."
   ]
  },
  {
   "cell_type": "code",
   "execution_count": 11,
   "metadata": {},
   "outputs": [
    {
     "name": "stdout",
     "output_type": "stream",
     "text": [
      "An unexpected error occurred: division by zero\n"
     ]
    }
   ],
   "source": [
    "try:\n",
    "    x = 10 / 0\n",
    "# except ZeroDivisionError:\n",
    "#     print(\"You can't divide by zero!\")\n",
    "# except ValueError:\n",
    "#     print(\"Value error occurred!\")\n",
    "except Exception as e:\n",
    "    print(f\"An unexpected error occurred: {e}\")"
   ]
  },
  {
   "cell_type": "markdown",
   "metadata": {},
   "source": [
    "### Catching Specific Exceptions\n",
    "\n",
    "You can catch specific exceptions using multiple except blocks to handle different error types separately."
   ]
  },
  {
   "cell_type": "code",
   "execution_count": 12,
   "metadata": {},
   "outputs": [
    {
     "ename": "ZeroDivisionError",
     "evalue": "division by zero",
     "output_type": "error",
     "traceback": [
      "\u001b[0;31m---------------------------------------------------------------------------\u001b[0m",
      "\u001b[0;31mZeroDivisionError\u001b[0m                         Traceback (most recent call last)",
      "Cell \u001b[0;32mIn[12], line 1\u001b[0m\n\u001b[0;32m----> 1\u001b[0m x \u001b[38;5;241m=\u001b[39m \u001b[38;5;241;43m10\u001b[39;49m\u001b[43m \u001b[49m\u001b[38;5;241;43m/\u001b[39;49m\u001b[43m \u001b[49m\u001b[38;5;241;43m0\u001b[39;49m\n",
      "\u001b[0;31mZeroDivisionError\u001b[0m: division by zero"
     ]
    }
   ],
   "source": [
    "x = 10 / 0"
   ]
  },
  {
   "cell_type": "code",
   "execution_count": 1,
   "metadata": {},
   "outputs": [
    {
     "name": "stdout",
     "output_type": "stream",
     "text": [
      "You can't divide by zero!\n"
     ]
    }
   ],
   "source": [
    "try:\n",
    "    x = 10 / 0\n",
    "except ZeroDivisionError:\n",
    "    print(\"You can't divide by zero!\")\n",
    "except ValueError:\n",
    "    print(\"Value error occurred!\")\n",
    "except Exception as e:\n",
    "    print(f\"An unexpected error occurred: {e}\")"
   ]
  },
  {
   "cell_type": "markdown",
   "metadata": {},
   "source": [
    "The generic Exception is used to catch any exception that wasn’t specifically handled. However, it’s best practice to catch specific exceptions when possible."
   ]
  },
  {
   "cell_type": "markdown",
   "metadata": {},
   "source": [
    "### Raising Exceptions"
   ]
  },
  {
   "cell_type": "markdown",
   "metadata": {},
   "source": [
    "In some cases, you might want to raise exceptions yourself using the raise keyword. This is useful when your program encounters a situation where continuing execution doesn’t make sense."
   ]
  },
  {
   "cell_type": "code",
   "execution_count": 13,
   "metadata": {},
   "outputs": [
    {
     "name": "stdout",
     "output_type": "stream",
     "text": [
      "Error: Age cannot be negative.\n"
     ]
    }
   ],
   "source": [
    "def check_age(age):\n",
    "    if age < 0:\n",
    "        raise ValueError(\"Age cannot be negative.\")\n",
    "    return age\n",
    "\n",
    "try:\n",
    "    age = check_age(-5)\n",
    "except ValueError as e:\n",
    "    print(f\"Error: {e}\")"
   ]
  },
  {
   "cell_type": "markdown",
   "metadata": {},
   "source": [
    "Here, the function raises a ValueError if the age is negative. The exception is caught in the try block and handled gracefully."
   ]
  },
  {
   "cell_type": "markdown",
   "metadata": {},
   "source": [
    "### The finally Block\n",
    "\n",
    "The finally block is used to execute code that should run regardless of whether an exception occurred or not. It’s useful for cleanup operations like closing files or releasing resources."
   ]
  },
  {
   "cell_type": "code",
   "execution_count": 15,
   "metadata": {},
   "outputs": [
    {
     "name": "stdout",
     "output_type": "stream",
     "text": [
      "File not found.\n"
     ]
    },
    {
     "ename": "NameError",
     "evalue": "name 'file' is not defined",
     "output_type": "error",
     "traceback": [
      "\u001b[0;31m---------------------------------------------------------------------------\u001b[0m",
      "\u001b[0;31mNameError\u001b[0m                                 Traceback (most recent call last)",
      "Cell \u001b[0;32mIn[15], line 7\u001b[0m\n\u001b[1;32m      5\u001b[0m     \u001b[38;5;28mprint\u001b[39m(\u001b[38;5;124m\"\u001b[39m\u001b[38;5;124mFile not found.\u001b[39m\u001b[38;5;124m\"\u001b[39m)\n\u001b[1;32m      6\u001b[0m \u001b[38;5;28;01mfinally\u001b[39;00m:\n\u001b[0;32m----> 7\u001b[0m     \u001b[43mfile\u001b[49m\u001b[38;5;241m.\u001b[39mclose()  \u001b[38;5;66;03m# This will always run, ensuring the file is closed\u001b[39;00m\n",
      "\u001b[0;31mNameError\u001b[0m: name 'file' is not defined"
     ]
    }
   ],
   "source": [
    "try:\n",
    "    file = open(\"example.txt\", \"r\")\n",
    "    # File operations\n",
    "except FileNotFoundError:\n",
    "    print(\"File not found.\")\n",
    "finally:\n",
    "    file.close()  # This will always run, ensuring the file is closed"
   ]
  },
  {
   "cell_type": "code",
   "execution_count": 16,
   "metadata": {},
   "outputs": [
    {
     "ename": "FileNotFoundError",
     "evalue": "[Errno 2] No such file or directory: 'example.txt'",
     "output_type": "error",
     "traceback": [
      "\u001b[0;31m---------------------------------------------------------------------------\u001b[0m",
      "\u001b[0;31mFileNotFoundError\u001b[0m                         Traceback (most recent call last)",
      "Cell \u001b[0;32mIn[16], line 1\u001b[0m\n\u001b[0;32m----> 1\u001b[0m file \u001b[38;5;241m=\u001b[39m \u001b[38;5;28;43mopen\u001b[39;49m\u001b[43m(\u001b[49m\u001b[38;5;124;43m\"\u001b[39;49m\u001b[38;5;124;43mexample.txt\u001b[39;49m\u001b[38;5;124;43m\"\u001b[39;49m\u001b[43m,\u001b[49m\u001b[43m \u001b[49m\u001b[38;5;124;43m\"\u001b[39;49m\u001b[38;5;124;43mr\u001b[39;49m\u001b[38;5;124;43m\"\u001b[39;49m\u001b[43m)\u001b[49m\n",
      "File \u001b[0;32m~/repos/python_basics/venv/lib/python3.11/site-packages/IPython/core/interactiveshell.py:324\u001b[0m, in \u001b[0;36m_modified_open\u001b[0;34m(file, *args, **kwargs)\u001b[0m\n\u001b[1;32m    317\u001b[0m \u001b[38;5;28;01mif\u001b[39;00m file \u001b[38;5;129;01min\u001b[39;00m {\u001b[38;5;241m0\u001b[39m, \u001b[38;5;241m1\u001b[39m, \u001b[38;5;241m2\u001b[39m}:\n\u001b[1;32m    318\u001b[0m     \u001b[38;5;28;01mraise\u001b[39;00m \u001b[38;5;167;01mValueError\u001b[39;00m(\n\u001b[1;32m    319\u001b[0m         \u001b[38;5;124mf\u001b[39m\u001b[38;5;124m\"\u001b[39m\u001b[38;5;124mIPython won\u001b[39m\u001b[38;5;124m'\u001b[39m\u001b[38;5;124mt let you open fd=\u001b[39m\u001b[38;5;132;01m{\u001b[39;00mfile\u001b[38;5;132;01m}\u001b[39;00m\u001b[38;5;124m by default \u001b[39m\u001b[38;5;124m\"\u001b[39m\n\u001b[1;32m    320\u001b[0m         \u001b[38;5;124m\"\u001b[39m\u001b[38;5;124mas it is likely to crash IPython. If you know what you are doing, \u001b[39m\u001b[38;5;124m\"\u001b[39m\n\u001b[1;32m    321\u001b[0m         \u001b[38;5;124m\"\u001b[39m\u001b[38;5;124myou can use builtins\u001b[39m\u001b[38;5;124m'\u001b[39m\u001b[38;5;124m open.\u001b[39m\u001b[38;5;124m\"\u001b[39m\n\u001b[1;32m    322\u001b[0m     )\n\u001b[0;32m--> 324\u001b[0m \u001b[38;5;28;01mreturn\u001b[39;00m \u001b[43mio_open\u001b[49m\u001b[43m(\u001b[49m\u001b[43mfile\u001b[49m\u001b[43m,\u001b[49m\u001b[43m \u001b[49m\u001b[38;5;241;43m*\u001b[39;49m\u001b[43margs\u001b[49m\u001b[43m,\u001b[49m\u001b[43m \u001b[49m\u001b[38;5;241;43m*\u001b[39;49m\u001b[38;5;241;43m*\u001b[39;49m\u001b[43mkwargs\u001b[49m\u001b[43m)\u001b[49m\n",
      "\u001b[0;31mFileNotFoundError\u001b[0m: [Errno 2] No such file or directory: 'example.txt'"
     ]
    }
   ],
   "source": [
    "file = open(\"example.txt\", \"r\")"
   ]
  },
  {
   "cell_type": "markdown",
   "metadata": {},
   "source": [
    "Even if the file isn’t found and an exception occurs, the finally block ensures that resources are cleaned up (in this case, closing the file). In this example the code fails as even when we have caught the error, the code in the `try` will not execute so the 'file' variable is not defined "
   ]
  },
  {
   "cell_type": "markdown",
   "metadata": {},
   "source": [
    "### Practical Example: Handling File Operations\n",
    "\n",
    "Let’s work on a practical example where we handle potential errors during file operations. We’ll handle a scenario where the file might not exist."
   ]
  },
  {
   "cell_type": "code",
   "execution_count": 2,
   "metadata": {},
   "outputs": [
    {
     "name": "stdout",
     "output_type": "stream",
     "text": [
      "The file you are trying to open does not exist.\n"
     ]
    }
   ],
   "source": [
    "try:\n",
    "    with open(\"nonexistent_file.txt\", \"r\") as file:\n",
    "        content = file.read()\n",
    "except FileNotFoundError:\n",
    "    print(\"The file you are trying to open does not exist.\")\n",
    "except Exception as e:\n",
    "    print(f\"An unexpected error occurred: {e}\")\n"
   ]
  },
  {
   "cell_type": "markdown",
   "metadata": {},
   "source": [
    "This will catch and handle the FileNotFoundError, displaying a user-friendly message instead of crashing the program."
   ]
  },
  {
   "cell_type": "markdown",
   "metadata": {},
   "source": [
    "### Exercise: Catching and Raising Exceptions\n",
    "\n",
    "Instructions:\n",
    "\n",
    "1. Write a function square_number(num) that raises a ValueError if the input is negative.\n",
    "2. In the try block, catch the exception and print an error message. If no exception occurs, print the square of the number."
   ]
  },
  {
   "cell_type": "code",
   "execution_count": 1,
   "metadata": {},
   "outputs": [
    {
     "name": "stdout",
     "output_type": "stream",
     "text": [
      "Error: invalid literal for int() with base 10: 'test'\n"
     ]
    }
   ],
   "source": [
    "def square_number(num):\n",
    "    if num < 0:\n",
    "        raise ValueError(\"The number cannot be negative.\")\n",
    "    return num ** 2\n",
    "\n",
    "try:\n",
    "    number = int(input(\"Enter a number: \"))\n",
    "    result = square_number(number)\n",
    "    print(\"The square of the number is:\", result)\n",
    "except ValueError as e:\n",
    "    print(f\"Error: {e}\")\n"
   ]
  },
  {
   "cell_type": "markdown",
   "metadata": {},
   "source": [
    "### Best Practices for Error Handling\n",
    "\n",
    "* Handle specific exceptions: Always catch specific exceptions rather than catching all exceptions with a generic Exception.\n",
    "* Avoid silent failures: Ensure that exceptions are logged or reported rather than passing without notification.\n",
    "* Use finally for cleanup: Always close files, database connections, or network resources in a finally block to avoid resource leaks.\n",
    "* Raise exceptions where necessary: Don’t hesitate to raise your own exceptions when input data or program state is invalid."
   ]
  }
 ],
 "metadata": {
  "kernelspec": {
   "display_name": "venv",
   "language": "python",
   "name": "python3"
  },
  "language_info": {
   "codemirror_mode": {
    "name": "ipython",
    "version": 3
   },
   "file_extension": ".py",
   "mimetype": "text/x-python",
   "name": "python",
   "nbconvert_exporter": "python",
   "pygments_lexer": "ipython3",
   "version": "3.11.1"
  }
 },
 "nbformat": 4,
 "nbformat_minor": 2
}
